Traceback (most recent call last):
  File "C:\Users\devar\AppData\Local\uv\cache\environments-v2\code1-559e9740f93abf95\Lib\site-packages\pandas\core\indexes\base.py", line 3812, in get_loc
    return self._engine.get_loc(casted_key)
           ~~~~~~~~~~~~~~~~~~~~^^^^^^^^^^^^
  File "pandas/_libs/index.pyx", line 167, in pandas._libs.index.IndexEngine.get_loc
  File "pandas/_libs/index.pyx", line 196, in pandas._libs.index.IndexEngine.get_loc
  File "pandas/_libs/hashtable_class_helper.pxi", line 7088, in pandas._libs.hashtable.PyObjectHashTable.get_item
  File "pandas/_libs/hashtable_class_helper.pxi", line 7096, in pandas._libs.hashtable.PyObjectHashTable.get_item
KeyError: 'Film Title'

The above exception was the direct cause of the following exception:

Traceback (most recent call last):
  File "C:\Dev\Code\iitm\tld\tds-proj-2-cloned\app\codes\task4\code1.py", line 12, in <module>
    f.write(earliest_film['Film Title'])
            ~~~~~~~~~~~~~^^^^^^^^^^^^^^
  File "C:\Users\devar\AppData\Local\uv\cache\environments-v2\code1-559e9740f93abf95\Lib\site-packages\pandas\core\series.py", line 1130, in __getitem__
    return self._get_value(key)
           ~~~~~~~~~~~~~~~^^^^^
  File "C:\Users\devar\AppData\Local\uv\cache\environments-v2\code1-559e9740f93abf95\Lib\site-packages\pandas\core\series.py", line 1246, in _get_value
    loc = self.index.get_loc(label)
  File "C:\Users\devar\AppData\Local\uv\cache\environments-v2\code1-559e9740f93abf95\Lib\site-packages\pandas\core\indexes\base.py", line 3819, in get_loc
    raise KeyError(key) from err
KeyError: 'Film Title'
